<?xml version="1.0"?>
  <robot name="amosero" xmlns:xacro="http://ros.org/wiki/xacro">

  <xacro:property name="width" value=".2" />
  <xacro:property name="bodylen" value=".6" />
<xacro:include filename="$(find amosero_description)/urdf/amosero_properties.urdf.xacro"/>
<xacro:include filename="$(find amosero_description)/urdf/common_properties.urdf.xacro"/>  



    <!-- Xacro properties -->
  <xacro:property name="M_SCALE" value="0.001"/>
  <xacro:property name="asus_xtion_pro_depth_rel_rgb_py" value="0.0270" />
  <xacro:property name="asus_xtion_pro_cam_rel_rgb_py"   value="-0.0220" />

  <!-- Parameterised in part by the values in amosero_properties.urdf.xacro -->
  <xacro:macro name="sensor_asus_xtion_pro" params="parent">
    <joint name="camera_rgb_joint" type="fixed">
      <origin xyz="${cam_px} ${cam_py} ${cam_pz}" 
              rpy="${cam_or} ${cam_op} ${cam_oy}"/>
      <parent link="${parent}"/>
      <child link="camera_rgb_frame" />
    </joint>

    <link name="camera_rgb_frame">
      <inertial>
        <mass value="0.001" />
        <origin xyz="0 0 0" />
        <inertia ixx="0.0001" ixy="0.0" ixz="0.0"
          iyy="0.0001" iyz="0.0"
          izz="0.0001" />
      </inertial>
    </link>

    <joint name="camera_rgb_optical_joint" type="fixed">
      <origin xyz="0 0 0" rpy="${-M_PI/2} 0 ${-M_PI/2}" />
      <parent link="camera_rgb_frame" />
      <child link="camera_rgb_optical_frame" />
    </joint>

    <link name="camera_rgb_optical_frame">
      <inertial>
        <mass value="0.001" />
        <origin xyz="0 0 0" />
        <inertia ixx="0.0001" ixy="0.0" ixz="0.0"
          iyy="0.0001" iyz="0.0"
          izz="0.0001" />
      </inertial>
    </link>

    <joint name="camera_joint" type="fixed">
      <origin xyz="0 ${asus_xtion_pro_cam_rel_rgb_py} 0" 
              rpy="0 0 0"/>
      <parent link="camera_rgb_frame"/>
      <child link="camera_link"/>
    </joint>
    <link name="camera_link">
      <visual>
        <origin xyz="-0.01 0 0" rpy="${-M_PI/2} -${M_PI} ${-M_PI/2}"/>
        <geometry>
          <mesh filename="package://amosero_description/meshes/sensors/asus_xtion_pro_live.dae" scale="${M_SCALE} ${M_SCALE} ${M_SCALE}"/>
        </geometry>
      </visual>
      <collision>
        <origin xyz="0.0 0.0 0.0" rpy="0 0 0" />
        <geometry>
        <box size="0.0730 .2760 0.0720"/>
      </geometry>
      </collision>
      <inertial>
        <mass value="0.01" />
        <origin xyz="0 0 0" />
        <inertia ixx="0.001" ixy="0.0" ixz="0.0"
          iyy="0.001" iyz="0.0"
          izz="0.001" />
      </inertial>
    </link>

    <joint name="camera_depth_joint" type="fixed">
      <origin xyz="0 ${asus_xtion_pro_depth_rel_rgb_py} 0" rpy="0 0 0" />
      <parent link="camera_rgb_frame" />
      <child link="camera_depth_frame" />
    </joint>

    <link name="camera_depth_frame">
      <inertial>
        <mass value="0.01" />
        <origin xyz="0 0 0" />
        <inertia ixx="0.001" ixy="0.0" ixz="0.0"
          iyy="0.001" iyz="0.0"
          izz="0.001" />
      </inertial>
    </link>

    <joint name="camera_depth_optical_joint" type="fixed">
      <origin xyz="0 0 0" rpy="${-M_PI/2} 0 ${-M_PI/2}" />
      <parent link="camera_depth_frame" />
      <child link="camera_depth_optical_frame" />
    </joint>

    <link name="camera_depth_optical_frame">
      <inertial>
        <mass value="0.001" />
        <origin xyz="0 0 0" />
        <inertia ixx="0.0001" ixy="0.0" ixz="0.0"
          iyy="0.0001" iyz="0.0"
          izz="0.0001" />
      </inertial>
    </link>

  <!-- RGBD sensor for simulation, same as Kinect -->
  <amosero_sim_3dsensor/>
  </xacro:macro>



    <link name="base_link">
      <visual>
        <geometry>
          <box size="0.2 .3 .1"/>
        </geometry>
        <origin rpy="0 0 0" xyz="0 0 0.05"/>
        <material_grey_blue/>
        <!--
        <material name="blue">
            <color rgba="0 0 .8 1"/>
        </material> -->

      </visual>
      <collision>
        <geometry>
           <box size="0.25 .35 .15"/>
        </geometry>
       </collision>
    </link>

    <sensor_asus_xtion_pro  parent="base_link"/>


<!-- 
    <link name="xtion2">
      <visual>
        <geometry>
          <box size="0.2 .05 .1"/>
        </geometry>
        <origin rpy="0 0 0" xyz="0 0 0"/>
        <material name="black">
          <color rgba="0 0 0 1"/>
        </material>
      </visual>
    </link>

    <joint name="base_to_xtion" type="fixed">
       <parent link="base_link"/>
       <child link="xtion2"/>
       
       <origin xyz="0 0.1 0.15"/>
    </joint>
-->

    <link name="wheel_1">
      <visual>
        <geometry>
          <cylinder length="0.05" radius="0.05"/>
        </geometry>
        <!--<origin rpy="0 1.5 0" xyz="0.1 0.1 0"/>-->
        <origin rpy="0 1.5 0" xyz="0 0 0"/>
          <material name="black">
            <color rgba="0 0 0 1"/>
          </material>
      </visual>
    </link>

    <link name="wheel_2">
      <visual>
        <geometry>
          <cylinder length="0.05" radius="0.05"/>
        </geometry>
        <!-- <origin rpy="0 1.5 0" xyz="-0.1 0.1 0"/> -->
        <origin rpy="0 1.5 0" xyz="0 0 0"/>
        <material name="black"/>
      </visual>
    </link>

    <link name="wheel_3">
      <visual>
        <geometry>
          <cylinder length="0.05" radius="0.05"/>
        </geometry>
        <!--  <origin rpy="0 1.5 0" xyz="0.1 -0.1 0"/> -->
        <origin rpy="0 1.5 0" xyz="0 0 0"/>
        <material name="black"/>
      </visual>
    </link>

    <link name="wheel_4">
      <visual>
        <geometry>
          <cylinder length="0.05" radius="0.05"/>
        </geometry>
        <!--   <origin rpy="0 1.5 0" xyz="-0.1 -0.1 0"/> -->
        <origin rpy="0 1.5 0" xyz="0 0 0"/>
        <material name="black"/>
      </visual>
    </link>

    <joint name="base_to_wheel1" type="continuous">
      <axis xyz="1 0 0"/>
      <parent link="base_link"/>
      <child link="wheel_1"/>
      <origin xyz="0.1 0.1 0"/>
      <limit effort="100" velocity="100"/>
      <joint_properties damping="0.0" friction="0.0"/>
    </joint>

    <joint name="base_to_wheel2" type="continuous">
      <axis xyz="1 0 0"/>
      <parent link="base_link"/>
      <child link="wheel_2"/>
      <origin xyz="-0.1 0.1 0"/>
      <limit effort="100" velocity="100"/>
      <joint_properties damping="0.0" friction="0.0"/>
    </joint>

    <joint name="base_to_wheel3" type="fixed">
      <parent link="base_link"/>
      <child link="wheel_3"/>
      <origin xyz="0.1 -0.1 0"/>
    </joint>

    <joint name="base_to_wheel4" type="fixed">
      <parent link="base_link"/>
      <child link="wheel_4"/>
      <origin xyz="-0.1 -0.1 0"/>
    </joint>

  </robot>