<?xml version="1.0"?>
  <robot name="amosero" xmlns:xacro="http://ros.org/wiki/xacro">

  <xacro:property name="width" value=".2" />
  <xacro:property name="bodylen" value=".6" />
  <xacro:include filename="$(find amosero_description)/urdf/amosero_properties.urdf.xacro"/>
  <xacro:include filename="$(find amosero_description)/urdf/common_properties.urdf.xacro"/>  



    <!-- Xacro properties -->
  <xacro:property name="M_SCALE" value="0.001"/>
  <!--<xacro:property name="asus_xtion_pro_depth_rel_rgb_py" value="0.0270" />
  <xacro:property name="asus_xtion_pro_cam_rel_rgb_py"   value="-0.0220" />-->
  <xacro:property name="asus_xtion_pro_depth_rel_rgb_py" value="0.0" />
  <xacro:property name="asus_xtion_pro_cam_rel_rgb_py"   value="-0.0" />

  <!-- Parameterised in part by the values in amosero_properties.urdf.xacro -->
  <xacro:macro name="sensor_asus_xtion_pro" params="parent">
    <joint name="camera_rgb_joint" type="fixed">
      <origin xyz="${cam_px} ${cam_py} ${cam_pz}" 
              rpy="${cam_or} ${cam_op} ${cam_oy}"/>
      <parent link="${parent}"/>
      <child link="camera_rgb_frame" />
    </joint>

    <link name="camera_rgb_frame">
      <inertial>
        <mass value="0.001" />
        <origin xyz="0 0 0" />
        <inertia ixx="0.0001" ixy="0.0" ixz="0.0"
          iyy="0.0001" iyz="0.0"
          izz="0.0001" />
      </inertial>
    </link>

    <joint name="camera_rgb_optical_joint" type="fixed">
      <origin xyz="0 0 0" rpy="${-M_PI/2} 0 ${-M_PI/2}" />
      <parent link="camera_rgb_frame" />
      <child link="camera_rgb_optical_frame" />
    </joint>

    <link name="camera_rgb_optical_frame">
      <inertial>
        <mass value="0.001" />
        <origin xyz="0 0 0" />
        <inertia ixx="0.0001" ixy="0.0" ixz="0.0"
          iyy="0.0001" iyz="0.0"
          izz="0.0001" />
      </inertial>
    </link>

    <joint name="camera_joint" type="fixed">
      <origin xyz="0 ${asus_xtion_pro_cam_rel_rgb_py} 0" 
              rpy="0 0 0"/>
      <parent link="camera_rgb_frame"/>
      <child link="camera_link"/>
    </joint>
    <link name="camera_link">
      <visual>
        <origin xyz="-0.01 0 0" rpy="${-M_PI/2} -${M_PI} ${-M_PI/2}"/>
        <geometry>
          <mesh filename="package://amosero_description/meshes/sensors/asus_xtion_pro_live.dae" scale="${M_SCALE} ${M_SCALE} ${M_SCALE}"/>
        </geometry>
      </visual>
      <collision>
        <origin xyz="0.0 0.0 0.0" rpy="0 0 0" />
        <geometry>
        <box size="0.0730 .2760 0.0720"/>
      </geometry>
      </collision>
      <inertial>
        <mass value="0.01" />
        <origin xyz="0 0 0" />
        <inertia ixx="0.001" ixy="0.0" ixz="0.0"
          iyy="0.001" iyz="0.0"
          izz="0.001" />
      </inertial>
    </link>

    <joint name="camera_depth_joint" type="fixed">
      <origin xyz="0 ${asus_xtion_pro_depth_rel_rgb_py} 0" rpy="0 0 0" />
      <parent link="camera_rgb_frame" />
      <child link="camera_depth_frame" />
    </joint>

    <link name="camera_depth_frame">
      <inertial>
        <mass value="0.01" />
        <origin xyz="0 0 0" />
        <inertia ixx="0.001" ixy="0.0" ixz="0.0"
          iyy="0.001" iyz="0.0"
          izz="0.001" />
      </inertial>
    </link>

    <joint name="camera_depth_optical_joint" type="fixed">
      <origin xyz="0 0 0" rpy="${-M_PI/2} 0 ${-M_PI/2}" />
      <parent link="camera_depth_frame" />
      <child link="camera_depth_optical_frame" />
    </joint>

    <link name="camera_depth_optical_frame">
      <inertial>
        <mass value="0.001" />
        <origin xyz="0 0 0" />
        <inertia ixx="0.0001" ixy="0.0" ixz="0.0"
          iyy="0.0001" iyz="0.0"
          izz="0.0001" />
      </inertial>
    </link>

  <!-- RGBD sensor for simulation, same as Kinect -->
  <amosero_sim_3dsensor/>
  </xacro:macro>



    <link name="base_link">
      <visual>
        <geometry>
          <box size=".2 .2 .025"/>
        </geometry>
        <origin rpy="0 0 0" xyz="0 0 0.025"/>
        <xacro:insert_block name="material_grey_blue" />
      </visual>
      <collision>
        <geometry>
           <box size="0.25 .25 .15"/>
        </geometry>
       </collision>
    </link>

    <link name="base_footprint">
      <visual>
        <geometry>
          <box size=".2 .2 .025"/>
        </geometry>
        <origin rpy="0 0 0" xyz="0 0 0"/>
        <xacro:insert_block name="material_light_grey" />
      </visual>
      <collision>
        <geometry>
           <box size="0.25 .25 .15"/>
        </geometry>
       </collision>
    </link>

    <joint name="base_footprint_to_base" type="fixed">
      <parent link="base_footprint"/>
      <child link="base_link"/>
      <origin xyz="0 0 0"/>      
    </joint>

    <sensor_asus_xtion_pro  parent="base_link"/>

    <link name="wheel_1">
      <visual>
        <geometry>
          <cylinder length="0.05" radius="0.05"/>
        </geometry>
        <!--<origin rpy="0 1.5 0" xyz="0.1 0.1 0"/>-->
        <origin rpy="${-M_PI/2} 0 0" xyz="0 0 0"/>
          <xacro:insert_block name="material_black" />
      </visual>
    </link>

     <link name="left_track_top_link">
      <visual>
        <geometry>
          <box size=".2 .05 .01"/>
        </geometry>
        <origin rpy="0 0 0" xyz="0 0 0"/>
        <xacro:insert_block name="material_black" />
      </visual>
      <collision>
        <geometry>
           <box size=".2 .05 .025"/>
        </geometry>
       </collision>
    </link>  

    <joint name="left_track_top_to_base" type="fixed">
      <parent link="base_footprint"/>
      <child link="left_track_top_link"/>
      <origin xyz="0 -0.1 0.0425"/>      
    </joint>

     <link name="left_track_bottom_link">
      <visual>
        <geometry>
          <box size=".2 .05 .01"/>
        </geometry>
        <origin rpy="0 0 0" xyz="0 0 0"/>
        <xacro:insert_block name="material_black" />
      </visual>
      <collision>
        <geometry>
           <box size=".2 .05 .025"/>
        </geometry>
       </collision>
    </link>  

    <joint name="left_track_bottom_to_base" type="fixed">
      <parent link="base_footprint"/>
      <child link="left_track_bottom_link"/>
      <origin xyz="0 -0.1 -0.0425"/>      
    </joint>



    <link name="wheel_3">
      <visual>
        <geometry>
          <cylinder length="0.05" radius="0.05"/>
        </geometry>
        <!--  <origin rpy="0 1.5 0" xyz="0.1 -0.1 0"/> -->
        <origin rpy="${-M_PI/2} 0 0" xyz="0 0 0"/>
        <xacro:insert_block name="material_black" />
      </visual>
    </link>

    <link name="wheel_2">
      <visual>
        <geometry>
          <cylinder length="0.05" radius="0.05"/>
        </geometry>
        <!-- <origin rpy="0 1.5 0" xyz="-0.1 0.1 0"/> -->
        <origin rpy="${-M_PI/2} 0 0" xyz="0 0 0"/>
        <xacro:insert_block name="material_black" />
      </visual>
    </link>

    <link name="wheel_4">
      <visual>
        <geometry>
          <cylinder length="0.05" radius="0.05"/>
        </geometry>
        <!--   <origin rpy="0 1.5 0" xyz="-0.1 -0.1 0"/> -->
        <origin rpy="${-M_PI/2} 0 0" xyz="0 0 0"/>
        <xacro:insert_block name="material_black" />
      </visual>
    </link>

    <link name="right_track_top_link">
      <visual>
        <geometry>
          <box size=".2 .05 .01"/>
        </geometry>
        <origin rpy="0 0 0" xyz="0 0 0"/>
        <xacro:insert_block name="material_black" />
      </visual>
      <collision>
        <geometry>
           <box size=".2 .05 .025"/>
        </geometry>
       </collision>
    </link>  

    <joint name="right_track_top_to_base" type="fixed">
      <parent link="base_footprint"/>
      <child link="right_track_top_link"/>
      <origin xyz="0 0.1 0.0425"/>      
    </joint>

     <link name="right_track_bottom_link">
      <visual>
        <geometry>
          <box size=".2 .05 .01"/>
        </geometry>
        <origin rpy="0 0 0" xyz="0 0 0"/>
        <xacro:insert_block name="material_black" />
      </visual>
      <collision>
        <geometry>
           <box size=".2 .05 .025"/>
        </geometry>
       </collision>
    </link>  

    <joint name="right_track_bottom_to_base" type="fixed">
      <parent link="base_footprint"/>
      <child link="right_track_bottom_link"/>
      <origin xyz="0 0.1 -0.0425"/>      
    </joint>



    <joint name="base_to_wheel1" type="continuous">
      <axis xyz="0 1 0"/>
      <parent link="base_footprint"/>
      <child link="wheel_1"/>
      <origin xyz="0.1 0.1 0"/>
      <limit effort="100" velocity="100"/>
      <joint_properties damping="0.0" friction="0.0"/>
    </joint>

    <joint name="base_to_wheel2" type="fixed">
      <axis xyz="0 1 0"/>
      <parent link="base_footprint"/>
      <child link="wheel_2"/>
      <origin xyz="-0.1 0.1 0"/>      
    </joint>

    <joint name="base_to_wheel3" type="continuous">
      <axis xyz="0 1 0"/>
      <parent link="base_footprint"/>
      <child link="wheel_3"/>
      <origin xyz="0.1 -0.1 0"/>
      <limit effort="100" velocity="100"/>
      <joint_properties damping="0.0" friction="0.0"/>
    </joint>

    <joint name="base_to_wheel4" type="fixed">
      <parent link="base_footprint"/>
      <child link="wheel_4"/>
      <origin xyz="-0.1 -0.1 0"/>
    </joint>

  </robot>